Workbook

Sheet Summary
A1: LITE | SUMMARY
A3: USD millions / shares millions except prices. Blue = inputs; black = formulas. Thesis horizon: 3–6 months.
A5: 3–6 MONTH THESIS | SENTIMENT RECOVERY REQUIRES INTACT EARNINGS
A6: The team expects a fear-driven discount to unwind over the next 1–2 earnings reports as AI infrastructure spending and optical shipments continue. The independent DCF below tests the thesis; it does not force a bullish target.
A8: Reference close: Sept 17 | B8: =Capital!B16 -> 893.61
B10: Bear | C10: Base | D10: Bull
A11: Gordon value / share | B11: =Bear!B66 -> 125.94095 | C11: =Base!B66 -> 268.02423 | D11: =Bull!B66 -> 300.2922
A12: Gordon upside / downside | B12: =Bear!B67 -> -0.85906497 | C12: =Base!B67 -> -0.70006577 | D12: =Bull!B67 -> -0.66395609
A13: Exit value / share | B13: =Bear!D66 -> 211.00521 | C13: =Base!D66 -> 448.34516 | D13: =Bull!D66 -> 498.52765
A14: Exit upside / downside | B14: =Bear!D67 -> -0.76387327 | C14: =Base!D67 -> -0.49827647 | D14: =Bull!D67 -> -0.44211943
A15: FY27 revenue | B15: =Bear!B20 -> 5600 | C15: =Base!B20 -> 6320 | D15: =Bull!B20 -> 6651.7801
A16: FY27 uFCF | B16: =Bear!B32 -> 183.8 | C16: =Base!B32 -> 654.52 | D16: =Bull!B32 -> 686.4356
A17: FY31 revenue | B17: =Bear!F20 -> 9035.9603 | C17: =Base!F20 -> 17527.679 | D17: =Bull!F20 -> 20003.567
A18: Terminal adjusted margin | B18: =Bear!K10 -> 0.25 | C18: =Base!K10 -> 0.25 | D18: =Bull!K10 -> 0.25
A19: Gordon TV / EV | B19: =Bear!B53 -> 0.40665956 | C19: =Base!B53 -> 0.39485117 | D19: =Bull!B53 -> 0.38311536
A21: Interpretation: the operating Bull case does not support the reference share price under the conservative component WACC and mature-margin fade. A 3–6 month rebound can occur despite this; do not label a sentiment/analyst recovery target as DCF-derived intrinsic value.
A24: Valuation date | B24: 2026-09-18
A25: FY27 remaining-year fraction | B25: =(DATE(2027,6,26)-DATE(2026,9,18))/365 -> 0.76986301
A27: Pure unwind to pre-event close | B27: ='Fear Unwind'!B7 -> 927.03
A28: Pure unwind upside | B28: ='Fear Unwind'!B14 -> 0.037398865
A29: Analyst average, 12-month benchmark | B29: =Comps!B16 -> 1149
A32: Navigation: Assumptions and Segments show each driver; Bull / Base / Bear contain the complete uFCF build; WACC and Capital show all components; Sensitivity includes both grids; Reverse DCF and Fear Unwind separate market-implied fundamentals from sentiment; Bear Liquidity tests survival.
A34: Formula outputs are cached and recalculate in Excel. Reverse solved inputs and price-implied discount rates require rerunning Python or Goal Seek after changes. June balance-sheet data and a prorated FY27 stub are disclosed simplifications. Slides are a snapshot of this build.

Sheet Assumptions
A1: LITE | ASSUMPTIONS
A3: USD millions / shares millions except prices. Blue = inputs; black = formulas. Thesis horizon: 3–6 months.
A5: Driver | B5: Value / path | C5: Logic / limitation | D5: Source
A6: Horizon | B6: 3–6 months | C6: Next 1–2 earnings reports test execution; DCF duration is separate. | D6: Team thesis
A7: Forecast length | B7: 5-year ramp + 5-year fade | C7: FY27–31 captures ramp; FY32–36 fades growth to 3% and adjusted margin to 25%. | D7: Team model
A8: Cloud / Industrial history | B8: FY25: 1,410.8 / 234.2 | C8: FY26 Industrial = FY25 × 1.05 estimate; Cloud is total less Industrial. Not reported FY26 segments. | D8: S2 / S5 + estimate
A9: Base revenue FY27 / FY28 | B9: 6,320 / 9,610 | C9: Public vendor consensus; later growth 30%,22%,15%,12%,9%,7%,5%,3%. No later consensus claim. | D9: S4 + team fade
A10: Bull EML share effect | B10: +1% → +3% → +1% | C10: Revenue uplift on baseline Cloud, a proxy for share/content gains; not a claimed measured EML market share. | D10: Team assumption
A11: Bull 1.6T mix effect | B11: +2% → +5% → +3% | C11: Separate external module mix premium; excludes internal component transfers and avoids intercompany double count. | D11: Team assumption; S1 direction
A12: Bull OCS increment | B12: 150 → 1,100 → 1,485 | C12: USD m added over the baseline Cloud path. OCS is part of Cloud; no claim this is disclosed backlog/revenue. | D12: Team assumption; S1 direction
A13: Internal sourcing margin | B13: +50 → +150 → 0 bps | C13: Increment to adjusted margin only; no extra revenue for internal laser transfers. | D13: Team assumption
A14: Adjusted EBIT margin | B14: ~41% → 42.5% peak → 25% | C14: Mature terminal 25% sits between COHR 21.8% and MRVL 36.6%; FN ~10% GAAP margin provides manufacturing context. | D14: S10/S11/S12; team terminal choice
A15: Recurring SBC + payroll | B15: 4.5% revenue | C15: Economic expense retained. Existing awards included separately; no recurring share-count escalator. | D15: S1 FY26 191.3/3,014=6.35%; assumed leverage
A16: Tax | B16: 20% | C16: Higher than FY26 adjusted 16.5%; common across scenarios. | D16: S1 + conservative estimate
... A24: Stub convention | B24: 0.770 years | C24: Uniform remaining FY27 cash generation; June cash held fixed. Approximation disclosed. | D24: Team convention

Sheet Segments
A1: LITE | SEGMENTS
A3: USD millions / shares millions except prices. Blue = inputs; black = formulas. Thesis horizon: 3–6 months.
A5: FORMER END-MARKET BUILD | FY26 ALLOCATION IS AN ESTIMATE
B6: FY2027 | C6: FY2028 | D6: FY2029 | E6: FY2030 | F6: FY2031 | G6: FY2032 | H6: FY2033 | I6: FY2034 | J6: FY2035 | K6: FY2036
A7: Base Cloud / Networking | B7: =B9-B8 -> 6059.3354 | C7: =C9-C8 -> 9333.6955 | D7: =D9-D8 -> 12200.117 | E7: =E9-E8 -> 14931.004 | F7: =F9-F8 -> 17198.596 | G7: =G9-G8 -> 19285.463 | H7: =H9-H8 -> 21038.432 | I7: =I9-I8 -> 22525.496 | ... K7: =K9-K8 -> 24368.949
A8: Base Industrial Tech | B8: =$B$23*(1+B17) -> 260.6646 | C8: =B8*(1+C17) -> 276.30448 | D8: =C8*(1+D17) -> 292.88274 | E8: =D8*(1+E17) -> 310.45571 | F8: =E8*(1+F17) -> 329.08305 | G8: =F8*(1+G17) -> 345.5372 | H8: =G8*(1+H17) -> 359.35869 | I8: =H8*(1+I17) -> 370.13945 | J8: =I8*(1+J17) -> 381.24364 | K8: =J8*(1+K17) -> 392.68095
A9: Base total revenue | B9: 6320 | C9: 9610 | D9: =C9*(1+D18) -> 12493 | E9: =D9*(1+E18) -> 15241.46 | F9: =E9*(1+F18) -> 17527.679 | G9: =F9*(1+G18) -> 19631 | H9: =G9*(1+H18) -> 21397.791 | I9: =H9*(1+I18) -> 22895.636 | J9: =I9*(1+J18) -> 24040.418 | K9: =J9*(1+K18) -> 24761.63
A10: EML revenue uplift vs Base Cloud | B10: 0.01 | C10: 0.015 | D10: 0.02 | E10: 0.025 | F10: 0.03 | G10: 0.03 | H10: 0.025 | I10: 0.02 | J10: 0.015 | K10: 0.01
A11: 1.6T revenue uplift vs Base Cloud | B11: 0.02 | C11: 0.03 | D11: 0.04 | E11: 0.045 | F11: 0.05 | G11: 0.05 | H11: 0.045 | I11: 0.04 | J11: 0.035 | K11: 0.03
A12: Incremental OCS revenue vs Base | B12: 150 | C12: 300 | D12: 550 | E12: 800 | F12: 1100 | G12: 1250 | H12: 1350 | I12: 1400 | J12: 1442 | K12: 1485.26
A13: Internal sourcing margin increment | B13: 0.005 | C13: 0.01 | D13: 0.015 | E13: 0.015 | F13: 0.015 | G13: 0.01 | H13: 0.0075 | I13: 0.005 | J13: 0.0025 | K13: 0
A14: Bull Cloud / Networking | B14: =B7*(1+B10+B11)+B12 -> 6391.1155 | C14: =C7*(1+C10+C11)+C12 -> 10053.712 | D14: =D7*(1+D10+D11)+D12 -> 13482.124 | E14: =E7*(1+E10+E11)+E12 -> 16776.175 | F14: =F7*(1+F10+F11)+F12 -> 19674.484 | G14: =G7*(1+G10+G11)+G12 -> 22078.3 | H14: =H7*(1+H10+H11)+H12 -> 23861.122 | I14: =I7*(1+I10+I11)+I12 -> 25277.026 | ... K14: =K7*(1+K10+K11)+K12 -> 26828.967
A15: Bull Industrial Tech | B15: =B8 -> 260.6646 | C15: =C8 -> 276.30448 | D15: =D8 -> 292.88274 | E15: =E8 -> 310.45571 | F15: =F8 -> 329.08305 | G15: =G8 -> 345.5372 | H15: =H8 -> 359.35869 | I15: =I8 -> 370.13945 | ... K15: =K8 -> 392.68095
A16: Bull total revenue | B16: =B14+B15 -> 6651.7801 | C16: =C14+C15 -> 10330.016 | D16: =D14+D15 -> 13775.007 | E16: =E14+E15 -> 17086.63 | F16: =F14+F15 -> 20003.567 | G16: =G14+G15 -> 22423.838 | H16: =H14+H15 -> 24220.481 | I16: =I14+I15 -> 25647.166 | ... K16: =K14+K15 -> 27221.648
A17: Industrial growth | B17: 0.06 | C17: 0.06 | D17: 0.06 | E17: 0.06 | F17: 0.06 | G17: 0.05 | H17: 0.04 | I17: 0.03 | J17: 0.03 | K17: 0.03
A18: Base total revenue growth | B18: =B9/$B$24-1 -> 1.0968812 | C18: =C9/B9-1 -> 0.52056962 | D18: 0.3 | E18: 0.22 | F18: 0.15 | G18: 0.12 | H18: 0.09 | I18: 0.07 | J18: 0.05 | K18: 0.03
A21: FY25 reported Industrial [S5] | B21: 234.2
A22: Estimated FY26 Industrial growth | B22: 0.05
A23: FY26 Industrial estimate | B23: =B21*(1+B22) -> 245.91
A24: FY26 reported total [S1] | B24: 3014
A25: FY26 Cloud estimate | B25: =B24-B23 -> 2768.09
A27: FY25 reported Cloud / Networking and Industrial Tech were $1,410.8m / $234.2m. FY26 switched to one reporting segment with Components / Systems product disclosure ($2,005.6m / $1,008.4m). The former-segment estimates above reconcile to the reported consolidated total; they are not company-disclosed FY26 end markets.
A29: Bull excess revenue is attributed only to LITE-specific EML share/content, 1.6T mix and incremental OCS. The percentages are revenue-impact proxies, not asserted actual market shares or disclosed mix percentages. Internal sourcing changes margin only. No internal component sale is counted twice.

Sheet Bull
A1: LITE | BULL
A3: USD millions / shares millions except prices. Blue = inputs; black = formulas. Thesis horizon: 3–6 months.
A5: FY27–31 RAMP + FY32–36 NORMALIZATION | BULL
B6: FY2027 | C6: FY2028 | D6: FY2029 | E6: FY2030 | F6: FY2031 | G6: FY2032 | H6: FY2033 | I6: FY2034 | J6: FY2035 | K6: FY2036
A8: Cloud revenue growth | B8: 1.3088539 | C8: 0.57307623 | D8: 0.34100962 | E8: 0.24432725 | F8: 0.1727634 | G8: 0.12217941 | H8: 0.080749953 | I8: 0.059339378 | J8: 0.039842761 | K8: 0.020728646
A9: Industrial revenue growth | B9: 0.06 | C9: 0.06 | D9: 0.06 | E9: 0.06 | F9: 0.06 | G9: 0.05 | H9: 0.04 | I9: 0.03 | J9: 0.03 | K9: 0.03
A10: Adjusted operating margin | B10: =Base!B10+Segments!B13 -> 0.4075 | C10: =Base!C10+Segments!C13 -> 0.425 | D10: =Base!D10+Segments!D13 -> 0.425 | E10: =Base!E10+Segments!E13 -> 0.415 | F10: =Base!F10+Segments!F13 -> 0.395 | G10: =Base!G10+Segments!G13 -> 0.36 | H10: =Base!H10+Segments!H13 -> 0.3275 | I10: =Base!I10+Segments!I13 -> 0.3 | ... K10: =Base!K10+Segments!K13 -> 0.25
A11: SBC and related payroll / sales | B11: 0.045 | C11: 0.045 | D11: 0.045 | E11: 0.045 | F11: 0.045 | G11: 0.045 | H11: 0.045 | I11: 0.045 | J11: 0.045 | K11: 0.045
A12: Cash tax rate | B12: =WACC!$B$19 -> 0.2 | C12: =WACC!$B$19 -> 0.2 | D12: =WACC!$B$19 -> 0.2 | E12: =WACC!$B$19 -> 0.2 | F12: =WACC!$B$19 -> 0.2 | G12: =WACC!$B$19 -> 0.2 | H12: =WACC!$B$19 -> 0.2 | I12: =WACC!$B$19 -> 0.2 | ... K12: =WACC!$B$19 -> 0.2
A13: Depreciation / sales | B13: 0.04 | C13: 0.045 | D13: 0.05 | E13: 0.055 | F13: 0.055 | G13: 0.055 | H13: 0.055 | I13: 0.055 | J13: 0.055 | K13: 0.055
A14: Capex / sales | B14: 0.13 | C14: 0.11 | D14: 0.095 | E14: 0.08 | F14: 0.075 | G14: 0.07 | H14: 0.065 | I14: 0.06 | J14: 0.06 | K14: 0.06
A15: Operating NWC / sales | B15: 0.18 | C15: 0.18 | D15: 0.18 | E15: 0.18 | F15: 0.18 | G15: 0.18 | H15: 0.18 | I15: 0.18 | J15: 0.18 | K15: 0.18
A18: Cloud / Networking revenue | B18: =Segments!B14 -> 6391.1155 | C18: =Segments!C14 -> 10053.712 | D18: =Segments!D14 -> 13482.124 | E18: =Segments!E14 -> 16776.175 | F18: =Segments!F14 -> 19674.484 | G18: =Segments!G14 -> 22078.3 | H18: =Segments!H14 -> 23861.122 | I18: =Segments!I14 -> 25277.026 | ... K18: =Segments!K14 -> 26828.967
A19: Industrial Tech revenue | B19: =Segments!B15 -> 260.6646 | C19: =Segments!C15 -> 276.30448 | D19: =Segments!D15 -> 292.88274 | E19: =Segments!E15 -> 310.45571 | F19: =Segments!F15 -> 329.08305 | G19: =Segments!G15 -> 345.5372 | H19: =Segments!H15 -> 359.35869 | I19: =Segments!I15 -> 370.13945 | ... K19: =Segments!K15 -> 392.68095
A20: Total revenue | B20: =B18+B19 -> 6651.7801 | C20: =C18+C19 -> 10330.016 | D20: =D18+D19 -> 13775.007 | E20: =E18+E19 -> 17086.63 | F20: =F18+F19 -> 20003.567 | G20: =G18+G19 -> 22423.838 | H20: =H18+H19 -> 24220.481 | I20: =I18+I19 -> 25647.166 | ... K20: =K18+K19 -> 27221.648
A21: Revenue growth | B21: =B20/Segments!$B$24-1 -> 1.2069609 | C21: =C20/B20-1 -> 0.55297021 | D21: =D20/C20-1 -> 0.33349325 | E21: =E20/D20-1 -> 0.2404081 | F21: =F20/E20-1 -> 0.17071455 | G21: =G20/F20-1 -> 0.12099197 | H21: =H20/G20-1 -> 0.080122022 | I21: =I20/H20-1 -> 0.05890407 | J21: =J20/I20-1 -> 0.039700711 | K21: =K20/J20-1 -> 0.020861202
A23: Adjusted EBIT | B23: =B20*B10 -> 2710.6004 | C23: =C20*C10 -> 4390.2569 | D23: =D20*D10 -> 5854.378 | E23: =E20*E10 -> 7090.9516 | F23: =F20*F10 -> 7901.4088 | G23: =G20*G10 -> 8072.5815 | H23: =H20*H10 -> 7932.2074 | I23: =I20*I10 -> 7694.1497 | ... K23: =K20*K10 -> 6805.412
A24: Less recurring SBC / payroll | B24: =B20*B11 -> 299.3301 | C24: =C20*C11 -> 464.85073 | D24: =D20*D11 -> 619.87532 | E24: =E20*E11 -> 768.89836 | F24: =F20*F11 -> 900.1605 | G24: =G20*G11 -> 1009.0727 | H24: =H20*H11 -> 1089.9216 | I24: =I20*I11 -> 1154.1225 | ... K24: =K20*K11 -> 1224.9742
A25: Economic EBIT | B25: =B23-B24 -> 2411.2703 | C25: =C23-C24 -> 3925.4062 | D25: =D23-D24 -> 5234.5027 | E25: =E23-E24 -> 6322.0532 | F25: =F23-F24 -> 7001.2483 | G25: =G23-G24 -> 7063.5088 | H25: =H23-H24 -> 6842.2858 | I25: =I23-I24 -> 6540.0272 | ... K25: =K23-K24 -> 5580.4379
A26: Cash operating taxes | B26: =B25*B12 -> 482.25405 | C26: =C25*C12 -> 785.08124 | D26: =D25*D12 -> 1046.9005 | E26: =E25*E12 -> 1264.4106 | F26: =F25*F12 -> 1400.2497 | G26: =G25*G12 -> 1412.7018 | H26: =H25*H12 -> 1368.4572 | I26: =I25*I12 -> 1308.0054 | ... K26: =K25*K12 -> 1116.0876
A27: NOPAT | B27: =B25-B26 -> 1929.0162 | C27: =C25-C26 -> 3140.325 | D27: =D25-D26 -> 4187.6021 | E27: =E25-E26 -> 5057.6426 | F27: =F25-F26 -> 5600.9987 | G27: =G25-G26 -> 5650.8071 | H27: =H25-H26 -> 5473.8286 | I27: =I25-I26 -> 5232.0218 | ... K27: =K25-K26 -> 4464.3503
A28: Add D&A: depreciation only | B28: =B20*B13 -> 266.0712 | C28: =C20*C13 -> 464.85073 | D28: =D20*D13 -> 688.75035 | E28: =E20*E13 -> 939.76467 | F28: =F20*F13 -> 1100.1962 | G28: =G20*G13 -> 1233.3111 | H28: =H20*H13 -> 1332.1264 | I28: =I20*I13 -> 1410.5941 | ... K28: =K20*K13 -> 1497.1906
A29: Less capex | B29: =B20*B14 -> 864.73141 | C29: =C20*C14 -> 1136.3018 | D29: =D20*D14 -> 1308.6257 | E29: =E20*E14 -> 1366.9304 | F29: =F20*F14 -> 1500.2675 | G29: =G20*G14 -> 1569.6686 | H29: =H20*H14 -> 1574.3312 | I29: =I20*I14 -> 1538.8299 | ... K29: =K20*K14 -> 1633.2989
A30: Operating NWC balance | B30: =B20*B15 -> 1197.3204 | C30: =C20*C15 -> 1859.4029 | D30: =D20*D15 -> 2479.5013 | E30: =E20*E15 -> 3075.5935 | F30: =F20*F15 -> 3600.642 | G30: =G20*G15 -> 4036.2908 | H30: =H20*H15 -> 4359.6865 | I30: =I20*I15 -> 4616.4898 | ... K30: =K20*K15 -> 4899.8967
A31: Less change in NWC | B31: =B30-Capital!$B$21 -> 643.92041 | C31: =C30-B30 -> 662.08252 | D31: =D30-C30 -> 620.09833 | E31: =E30-D30 -> 596.09219 | F31: =F30-E30 -> 525.04855 | G31: =G30-F30 -> 435.64876 | H31: =H30-G30 -> 323.39578 | I31: =I30-H30 -> 256.80328 | J31: =J30-I30 -> 183.27793 | K31: =K30-J30 -> 100.12892
A32: UNLEVERED FREE CASH FLOW | B32: =B27+B28-B29-B31 -> 686.4356 | C32: =C27+C28-C29-C31 -> 1806.7914 | D32: =D27+D28-D29-D31 -> 2947.6285 | E32: =E27+E28-E29-E31 -> 4034.3846 | F32: =F27+F28-F29-F31 -> 4675.8788 | G32: =G27+G28-G29-G31 -> 4878.8007 | H32: =H27+H28-H29-H31 -> 4908.2281 | I32: =I27+I28-I29-I31 -> 4846.9827 | ... K32: =K27+K28-K29-K31 -> 4228.1131
A33: Economic EBIT margin | B33: =B25/B20 -> 0.3625 | C33: =C25/C20 -> 0.38 | D33: =D25/D20 -> 0.38 | E33: =E25/E20 -> 0.37 | F33: =F25/F20 -> 0.35 | G33: =G25/G20 -> 0.315 | H33: =H25/H20 -> 0.2825 | I33: =I25/I20 -> 0.255 | ... K33: =K25/K20 -> 0.205
A34: Economic EBITDA | B34: =B25+B28 -> 2677.3415 | C34: =C25+C28 -> 4390.2569 | D34: =D25+D28 -> 5923.253 | E34: =E25+E28 -> 7261.8179 | F34: =F25+F28 -> 8101.4445 | G34: =G25+G28 -> 8296.8199 | H34: =H25+H28 -> 8174.4123 | I34: =I25+I28 -> 7950.6213 | ... K34: =K25+K28 -> 7077.6285
A36: Remaining-year fraction | B36: =Summary!$B$25 -> 0.76986301 | C36: =1 -> 1 | D36: =1 -> 1 | E36: =1 -> 1 | F36: =1 -> 1 | G36: =1 -> 1 | H36: =1 -> 1 | I36: =1 -> 1 | J36: =1 -> 1 | K36: =1 -> 1
A37: Discount years | B37: =Summary!$B$25+0 -> 0.76986301 | C37: =Summary!$B$25+1 -> 1.769863 | D37: =Summary!$B$25+2 -> 2.769863 | E37: =Summary!$B$25+3 -> 3.769863 | F37: =Summary!$B$25+4 -> 4.769863 | G37: =Summary!$B$25+5 -> 5.769863 | H37: =Summary!$B$25+6 -> 6.769863 | I37: =Summary!$B$25+7 -> 7.769863 | J37: =Summary!$B$25+8 -> 8.769863 | K37: =Summary!$B$25+9 -> 9.769863
A38: Discount factor | B38: =1/(1+WACC!$B$26)^B37 -> 0.90420477 | C38: =1/(1+WACC!$B$26)^C37 -> 0.79334176 | D38: =1/(1+WACC!$B$26)^D37 -> 0.69607147 | E38: =1/(1+WACC!$B$26)^E37 -> 0.61072733 | F38: =1/(1+WACC!$B$26)^F37 -> 0.53584709 | G38: =1/(1+WACC!$B$26)^G37 -> 0.47014778 | H38: =1/(1+WACC!$B$26)^H37 -> 0.41250376 | I38: =1/(1+WACC!$B$26)^I37 -> 0.36192738 | ... K38: =1/(1+WACC!$B$26)^K37 -> 0.27861755
A39: PV of uFCF | B39: =B32*B36*B38 -> 477.8373 | C39: =C32*C36*C38 -> 1433.403 | D39: =D32*D36*D38 -> 2051.7601 | E39: =E32*E36*E38 -> 2463.9089 | F39: =F32*F36*F38 -> 2505.556 | G39: =G32*G36*G38 -> 2293.7574 | H39: =H32*H36*H38 -> 2024.6625 | I39: =I32*I36*I38 -> 1754.2557 | ... K39: =K32*K36*K38 -> 1178.0265
A41: TERMINAL VALUE: GORDON GROWTH AND MATURE EXIT EBITDA MULTIPLE
B42: Gordon | D42: Exit method
A43: Terminal revenue | B43: =K20*(1+WACC!B30) -> 28038.298
A44: Terminal NOPAT | B44: =B43*(K10-K11)*(1-K12) -> 4598.2808
A45: Terminal depreciation | B45: =B43*K13 -> 1542.1064
A46: Terminal capex | B46: =B43*K14 -> 1682.2979
A47: Terminal delta NWC | B47: =B43*K15-K30 -> 146.9969
A48: Normalized terminal uFCF | B48: =B44+B45-B46-B47 -> 4311.0924
...

Sheet Base
A1: LITE | BASE
A3: USD millions / shares millions except prices. Blue = inputs; black = formulas. Thesis horizon: 3–6 months.
A5: FY27–31 RAMP + FY32–36 NORMALIZATION | BASE
B6: FY2027 | C6: FY2028 | D6: FY2029 | E6: FY2030 | F6: FY2031 | G6: FY2032 | H6: FY2033 | I6: FY2034 | J6: FY2035 | K6: FY2036
A8: Cloud revenue growth | B8: 1.1889951 | C8: 0.54038272 | D8: 0.3071047 | E8: 0.22384105 | F8: 0.15187134 | G8: 0.1213394 | H8: 0.090895849 | I8: 0.070683242 | J8: 0.05032864 | K8: 0.03
A9: Industrial revenue growth | B9: 0.06 | C9: 0.06 | D9: 0.06 | E9: 0.06 | F9: 0.06 | G9: 0.05 | H9: 0.04 | I9: 0.03 | J9: 0.03 | K9: 0.03
A10: Adjusted operating margin | B10: 0.4025 | C10: 0.415 | D10: 0.41 | E10: 0.4 | F10: 0.38 | G10: 0.35 | H10: 0.32 | I10: 0.295 | J10: 0.27 | K10: 0.25
A11: SBC and related payroll / sales | B11: 0.045 | C11: 0.045 | D11: 0.045 | E11: 0.045 | F11: 0.045 | G11: 0.045 | H11: 0.045 | I11: 0.045 | J11: 0.045 | K11: 0.045
A12: Cash tax rate | B12: =WACC!$B$19 -> 0.2 | C12: =WACC!$B$19 -> 0.2 | D12: =WACC!$B$19 -> 0.2 | E12: =WACC!$B$19 -> 0.2 | F12: =WACC!$B$19 -> 0.2 | G12: =WACC!$B$19 -> 0.2 | H12: =WACC!$B$19 -> 0.2 | I12: =WACC!$B$19 -> 0.2 | ... K12: =WACC!$B$19 -> 0.2
A13: Depreciation / sales | B13: 0.04 | C13: 0.045 | D13: 0.05 | E13: 0.055 | F13: 0.055 | G13: 0.055 | H13: 0.055 | I13: 0.055 | J13: 0.055 | K13: 0.055
A14: Capex / sales | B14: 0.13 | C14: 0.11 | D14: 0.095 | E14: 0.08 | F14: 0.075 | G14: 0.07 | H14: 0.065 | I14: 0.06 | J14: 0.06 | K14: 0.06
A15: Operating NWC / sales | B15: 0.18 | C15: 0.18 | D15: 0.18 | E15: 0.18 | F15: 0.18 | G15: 0.18 | H15: 0.18 | I15: 0.18 | J15: 0.18 | K15: 0.18
A18: Cloud / Networking revenue | B18: =Segments!B7 -> 6059.3354 | C18: =Segments!C7 -> 9333.6955 | D18: =Segments!D7 -> 12200.117 | E18: =Segments!E7 -> 14931.004 | F18: =Segments!F7 -> 17198.596 | G18: =Segments!G7 -> 19285.463 | H18: =Segments!H7 -> 21038.432 | I18: =Segments!I7 -> 22525.496 | ... K18: =Segments!K7 -> 24368.949
A19: Industrial Tech revenue | B19: =Segments!B8 -> 260.6646 | C19: =Segments!C8 -> 276.30448 | D19: =Segments!D8 -> 292.88274 | E19: =Segments!E8 -> 310.45571 | F19: =Segments!F8 -> 329.08305 | G19: =Segments!G8 -> 345.5372 | H19: =Segments!H8 -> 359.35869 | I19: =Segments!I8 -> 370.13945 | ... K19: =Segments!K8 -> 392.68095
A20: Total revenue | B20: =B18+B19 -> 6320 | C20: =C18+C19 -> 9610 | D20: =D18+D19 -> 12493 | E20: =E18+E19 -> 15241.46 | F20: =F18+F19 -> 17527.679 | G20: =G18+G19 -> 19631 | H20: =H18+H19 -> 21397.791 | I20: =I18+I19 -> 22895.636 | ... K20: =K18+K19 -> 24761.63
A21: Revenue growth | B21: =B20/Segments!$B$24-1 -> 1.0968812 | C21: =C20/B20-1 -> 0.52056962 | D21: =D20/C20-1 -> 0.3 | E21: =E20/D20-1 -> 0.22 | F21: =F20/E20-1 -> 0.15 | G21: =G20/F20-1 -> 0.12 | H21: =H20/G20-1 -> 0.09 | I21: =I20/H20-1 -> 0.07 | J21: =J20/I20-1 -> 0.05 | K21: =K20/J20-1 -> 0.03
A23: Adjusted EBIT | B23: =B20*B10 -> 2543.8 | C23: =C20*C10 -> 3988.15 | D23: =D20*D10 -> 5122.13 | E23: =E20*E10 -> 6096.584 | F23: =F20*F10 -> 6660.518 | G23: =G20*G10 -> 6870.8502 | H23: =H20*H10 -> 6847.293 | I23: =I20*I10 -> 6754.2126 | ... K23: =K20*K10 -> 6190.4075
A24: Less recurring SBC / payroll | B24: =B20*B11 -> 284.4 | C24: =C20*C11 -> 432.45 | D24: =D20*D11 -> 562.185 | E24: =E20*E11 -> 685.8657 | F24: =F20*F11 -> 788.74555 | G24: =G20*G11 -> 883.39502 | H24: =H20*H11 -> 962.90057 | I24: =I20*I11 -> 1030.3036 | ... K24: =K20*K11 -> 1114.2734
A25: Economic EBIT | B25: =B23-B24 -> 2259.4 | C25: =C23-C24 -> 3555.7 | D25: =D23-D24 -> 4559.945 | E25: =E23-E24 -> 5410.7183 | F25: =F23-F24 -> 5871.7725 | G25: =G23-G24 -> 5987.4551 | H25: =H23-H24 -> 5884.3924 | I25: =I23-I24 -> 5723.909 | ... K25: =K23-K24 -> 5076.1342
A26: Cash operating taxes | B26: =B25*B12 -> 451.88 | C26: =C25*C12 -> 711.14 | D26: =D25*D12 -> 911.989 | E26: =E25*E12 -> 1082.1437 | F26: =F25*F12 -> 1174.3545 | G26: =G25*G12 -> 1197.491 | H26: =H25*H12 -> 1176.8785 | I26: =I25*I12 -> 1144.7818 | ... K26: =K25*K12 -> 1015.2268
A27: NOPAT | B27: =B25-B26 -> 1807.52 | C27: =C25-C26 -> 2844.56 | D27: =D25-D26 -> 3647.956 | E27: =E25-E26 -> 4328.5746 | F27: =F25-F26 -> 4697.418 | G27: =G25-G26 -> 4789.9641 | H27: =H25-H26 -> 4707.5139 | I27: =I25-I26 -> 4579.1272 | ... K27: =K25-K26 -> 4060.9073
A28: Add D&A: depreciation only | B28: =B20*B13 -> 252.8 | C28: =C20*C13 -> 432.45 | D28: =D20*D13 -> 624.65 | E28: =E20*E13 -> 838.2803 | F28: =F20*F13 -> 964.02234 | G28: =G20*G13 -> 1079.705 | H28: =H20*H13 -> 1176.8785 | I28: =I20*I13 -> 1259.26 | ... K28: =K20*K13 -> 1361.8897
A29: Less capex | B29: =B20*B14 -> 821.6 | C29: =C20*C14 -> 1057.1 | D29: =D20*D14 -> 1186.835 | E29: =E20*E14 -> 1219.3168 | F29: =F20*F14 -> 1314.5759 | G29: =G20*G14 -> 1374.17 | H29: =H20*H14 -> 1390.8564 | I29: =I20*I14 -> 1373.7382 | ... K29: =K20*K14 -> 1485.6978
A30: Operating NWC balance | B30: =B20*B15 -> 1137.6 | C30: =C20*C15 -> 1729.8 | D30: =D20*D15 -> 2248.74 | E30: =E20*E15 -> 2743.4628 | F30: =F20*F15 -> 3154.9822 | G30: =G20*G15 -> 3533.5801 | H30: =H20*H15 -> 3851.6023 | I30: =I20*I15 -> 4121.2145 | ... K30: =K20*K15 -> 4457.0934
A31: Less change in NWC | B31: =B30-Capital!$B$21 -> 584.2 | C31: =C30-B30 -> 592.2 | D31: =D30-C30 -> 518.94 | E31: =E30-D30 -> 494.7228 | F31: =F30-E30 -> 411.51942 | G31: =G30-F30 -> 378.59787 | H31: =H30-G30 -> 318.02221 | I31: =I30-H30 -> 269.61216 | J31: =J30-I30 -> 206.06072 | K31: =K30-J30 -> 129.81826
A32: UNLEVERED FREE CASH FLOW | B32: =B27+B28-B29-B31 -> 654.52 | C32: =C27+C28-C29-C31 -> 1627.71 | D32: =D27+D28-D29-D31 -> 2566.831 | E32: =E27+E28-E29-E31 -> 3452.8153 | F32: =F27+F28-F29-F31 -> 3935.345 | G32: =G27+G28-G29-G31 -> 4116.9012 | H32: =H27+H28-H29-H31 -> 4175.5138 | I32: =I27+I28-I29-I31 -> 4195.0368 | ... K32: =K27+K28-K29-K31 -> 3807.2809
A33: Economic EBIT margin | B33: =B25/B20 -> 0.3575 | C33: =C25/C20 -> 0.37 | D33: =D25/D20 -> 0.365 | E33: =E25/E20 -> 0.355 | F33: =F25/F20 -> 0.335 | G33: =G25/G20 -> 0.305 | H33: =H25/H20 -> 0.275 | I33: =I25/I20 -> 0.25 | ... K33: =K25/K20 -> 0.205
A34: Economic EBITDA | B34: =B25+B28 -> 2512.2 | C34: =C25+C28 -> 3988.15 | D34: =D25+D28 -> 5184.595 | E34: =E25+E28 -> 6248.9986 | F34: =F25+F28 -> 6835.7948 | G34: =G25+G28 -> 7067.1602 | H34: =H25+H28 -> 7061.2709 | I34: =I25+I28 -> 6983.1689 | ... K34: =K25+K28 -> 6438.0238
A36: Remaining-year fraction | B36: =Summary!$B$25 -> 0.76986301 | C36: =1 -> 1 | D36: =1 -> 1 | E36: =1 -> 1 | F36: =1 -> 1 | G36: =1 -> 1 | H36: =1 -> 1 | I36: =1 -> 1 | J36: =1 -> 1 | K36: =1 -> 1
A37: Discount years | B37: =Summary!$B$25+0 -> 0.76986301 | C37: =Summary!$B$25+1 -> 1.769863 | D37: =Summary!$B$25+2 -> 2.769863 | E37: =Summary!$B$25+3 -> 3.769863 | F37: =Summary!$B$25+4 -> 4.769863 | G37: =Summary!$B$25+5 -> 5.769863 | H37: =Summary!$B$25+6 -> 6.769863 | I37: =Summary!$B$25+7 -> 7.769863 | J37: =Summary!$B$25+8 -> 8.769863 | K37: =Summary!$B$25+9 -> 9.769863
A38: Discount factor | B38: =1/(1+WACC!$B$26)^B37 -> 0.90420477 | C38: =1/(1+WACC!$B$26)^C37 -> 0.79334176 | D38: =1/(1+WACC!$B$26)^D37 -> 0.69607147 | E38: =1/(1+WACC!$B$26)^E37 -> 0.61072733 | F38: =1/(1+WACC!$B$26)^F37 -> 0.53584709 | G38: =1/(1+WACC!$B$26)^G37 -> 0.47014778 | H38: =1/(1+WACC!$B$26)^H37 -> 0.41250376 | I38: =1/(1+WACC!$B$26)^I37 -> 0.36192738 | ... K38: =1/(1+WACC!$B$26)^K37 -> 0.27861755
A39: PV of uFCF | B39: =B32*B36*B38 -> 455.62041 | C39: =C32*C36*C38 -> 1291.3303 | D39: =D32*D36*D38 -> 1786.6978 | E39: =E32*E36*E38 -> 2108.7287 | F39: =F32*F36*F38 -> 2108.7431 | G39: =G32*G36*G38 -> 1935.552 | H39: =H32*H36*H38 -> 1722.4152 | I39: =I32*I36*I38 -> 1518.2987 | ... K39: =K32*K36*K38 -> 1060.7753
A41: TERMINAL VALUE: GORDON GROWTH AND MATURE EXIT EBITDA MULTIPLE
B42: Gordon | D42: Exit method
A43: Terminal revenue | B43: =K20*(1+WACC!B30) -> 25504.479
A44: Terminal NOPAT | B44: =B43*(K10-K11)*(1-K12) -> 4182.7346
A45: Terminal depreciation | B45: =B43*K13 -> 1402.7463
A46: Terminal capex | B46: =B43*K14 -> 1530.2687
A47: Terminal delta NWC | B47: =B43*K15-K30 -> 133.7128
A48: Normalized terminal uFCF | B48: =B44+B45-B46-B47 -> 3921.4994
...

Sheet Bear
A1: LITE | BEAR
A3: USD millions / shares millions except prices. Blue = inputs; black = formulas. Thesis horizon: 3–6 months.
A5: FY27–31 RAMP + FY32–36 NORMALIZATION | BEAR
B6: FY2027 | C6: FY2028 | D6: FY2029 | E6: FY2030 | F6: FY2031 | G6: FY2032 | H6: FY2033 | I6: FY2034 | J6: FY2035 | K6: FY2036
A8: Cloud revenue growth | B8: 0.92912803 | C8: 0.2 | D8: 0.15 | E8: 0.1 | F8: 0.08 | G8: 0.06 | H8: 0.05 | I8: 0.04 | J8: 0.03 | K8: 0.03
A9: Industrial revenue growth | B9: 0.057297385 | C9: 0 | D9: 0.02 | E9: 0.03 | F9: 0.03 | G9: 0.03 | H9: 0.03 | I9: 0.03 | J9: 0.03 | K9: 0.03
A10: Adjusted operating margin | B10: 0.35 | C10: 0.34 | D10: 0.33 | E10: 0.32 | F10: 0.31 | G10: 0.29 | H10: 0.275 | I10: 0.26 | J10: 0.25 | K10: 0.25
A11: SBC and related payroll / sales | B11: 0.045 | C11: 0.045 | D11: 0.045 | E11: 0.045 | F11: 0.045 | G11: 0.045 | H11: 0.045 | I11: 0.045 | J11: 0.045 | K11: 0.045
A12: Cash tax rate | B12: =WACC!$B$19 -> 0.2 | C12: =WACC!$B$19 -> 0.2 | D12: =WACC!$B$19 -> 0.2 | E12: =WACC!$B$19 -> 0.2 | F12: =WACC!$B$19 -> 0.2 | G12: =WACC!$B$19 -> 0.2 | H12: =WACC!$B$19 -> 0.2 | I12: =WACC!$B$19 -> 0.2 | ... K12: =WACC!$B$19 -> 0.2
A13: Depreciation / sales | B13: 0.04 | C13: 0.045 | D13: 0.05 | E13: 0.055 | F13: 0.055 | G13: 0.055 | H13: 0.055 | I13: 0.055 | J13: 0.055 | K13: 0.055
A14: Capex / sales | B14: 0.13 | C14: 0.11 | D14: 0.095 | E14: 0.08 | F14: 0.075 | G14: 0.07 | H14: 0.065 | I14: 0.06 | J14: 0.06 | K14: 0.06
A15: Operating NWC / sales | B15: 0.22 | C15: 0.22 | D15: 0.22 | E15: 0.22 | F15: 0.22 | G15: 0.22 | H15: 0.22 | I15: 0.22 | J15: 0.22 | K15: 0.22
A18: Cloud / Networking revenue | B18: 5340 | C18: =B18*(1+C8) -> 6408 | D18: =C18*(1+D8) -> 7369.2 | E18: =D18*(1+E8) -> 8106.12 | F18: =E18*(1+F8) -> 8754.6096 | G18: =F18*(1+G8) -> 9279.8862 | H18: =G18*(1+H8) -> 9743.8805 | I18: =H18*(1+I8) -> 10133.636 | J18: =I18*(1+J8) -> 10437.645 | K18: =J18*(1+K8) -> 10750.774
A19: Industrial Tech revenue | B19: 260 | C19: =B19*(1+C9) -> 260 | D19: =C19*(1+D9) -> 265.2 | E19: =D19*(1+E9) -> 273.156 | F19: =E19*(1+F9) -> 281.35068 | G19: =F19*(1+G9) -> 289.7912 | H19: =G19*(1+H9) -> 298.48494 | I19: =H19*(1+I9) -> 307.43948 | J19: =I19*(1+J9) -> 316.66267 | K19: =J19*(1+K9) -> 326.16255
A20: Total revenue | B20: =B18+B19 -> 5600 | C20: =C18+C19 -> 6668 | D20: =D18+D19 -> 7634.4 | E20: =E18+E19 -> 8379.276 | F20: =F18+F19 -> 9035.9603 | G20: =G18+G19 -> 9569.6774 | H20: =H18+H19 -> 10042.365 | I20: =I18+I19 -> 10441.075 | ... K20: =K18+K19 -> 11076.937
A21: Revenue growth | B21: =B20/Segments!$B$24-1 -> 0.85799602 | C21: =C20/B20-1 -> 0.19071429 | D21: =D20/C20-1 -> 0.14493101 | E21: =E20/D20-1 -> 0.097568375 | F21: =F20/E20-1 -> 0.07837005 | G21: =G20/F20-1 -> 0.059065897 | H21: =H20/G20-1 -> 0.049394355 | I21: =I20/H20-1 -> 0.039702774 | J21: =J20/I20-1 -> 0.03 | K21: =K20/J20-1 -> 0.03
A23: Adjusted EBIT | B23: =B20*B10 -> 1960 | C23: =C20*C10 -> 2267.12 | D23: =D20*D10 -> 2519.352 | E23: =E20*E10 -> 2681.3683 | F23: =F20*F10 -> 2801.1477 | G23: =G20*G10 -> 2775.2064 | H23: =H20*H10 -> 2761.6505 | I23: =I20*I10 -> 2714.6795 | ... K23: =K20*K10 -> 2769.2342
A24: Less recurring SBC / payroll | B24: =B20*B11 -> 252 | C24: =C20*C11 -> 300.06 | D24: =D20*D11 -> 343.548 | E24: =E20*E11 -> 377.06742 | F24: =F20*F11 -> 406.61821 | G24: =G20*G11 -> 430.63548 | H24: =H20*H11 -> 451.90644 | I24: =I20*I11 -> 469.84838 | ... K24: =K20*K11 -> 498.46215
A25: Economic EBIT | B25: =B23-B24 -> 1708 | C25: =C23-C24 -> 1967.06 | D25: =D23-D24 -> 2175.804 | E25: =E23-E24 -> 2304.3009 | F25: =F23-F24 -> 2394.5295 | G25: =G23-G24 -> 2344.571 | H25: =H23-H24 -> 2309.744 | I25: =I23-I24 -> 2244.8312 | ... K25: =K23-K24 -> 2270.772
A26: Cash operating taxes | B26: =B25*B12 -> 341.6 | C26: =C25*C12 -> 393.412 | D26: =D25*D12 -> 435.1608 | E26: =E25*E12 -> 460.86018 | F26: =F25*F12 -> 478.90589 | G26: =G25*G12 -> 468.91419 | H26: =H25*H12 -> 461.94881 | I26: =I25*I12 -> 448.96623 | ... K26: =K25*K12 -> 454.1544
A27: NOPAT | B27: =B25-B26 -> 1366.4 | C27: =C25-C26 -> 1573.648 | D27: =D25-D26 -> 1740.6432 | E27: =E25-E26 -> 1843.4407 | F27: =F25-F26 -> 1915.6236 | G27: =G25-G26 -> 1875.6568 | H27: =H25-H26 -> 1847.7952 | I27: =I25-I26 -> 1795.8649 | ... K27: =K25-K26 -> 1816.6176
A28: Add D&A: depreciation only | B28: =B20*B13 -> 224 | C28: =C20*C13 -> 300.06 | D28: =D20*D13 -> 381.72 | E28: =E20*E13 -> 460.86018 | F28: =F20*F13 -> 496.97782 | G28: =G20*G13 -> 526.33226 | H28: =H20*H13 -> 552.3301 | I28: =I20*I13 -> 574.25914 | ... K28: =K20*K13 -> 609.23152
A29: Less capex | B29: =B20*B14 -> 728 | C29: =C20*C14 -> 733.48 | D29: =D20*D14 -> 725.268 | E29: =E20*E14 -> 670.34208 | F29: =F20*F14 -> 677.69702 | G29: =G20*G14 -> 669.87742 | H29: =H20*H14 -> 652.75375 | I29: =I20*I14 -> 626.46451 | ... K29: =K20*K14 -> 664.6162
A30: Operating NWC balance | B30: =B20*B15 -> 1232 | C30: =C20*C15 -> 1466.96 | D30: =D20*D15 -> 1679.568 | E30: =E20*E15 -> 1843.4407 | F30: =F20*F15 -> 1987.9113 | G30: =G20*G15 -> 2105.329 | H30: =H20*H15 -> 2209.3204 | I30: =I20*I15 -> 2297.0365 | ... K30: =K20*K15 -> 2436.9261
A31: Less change in NWC | B31: =B30-Capital!$B$21 -> 678.6 | C31: =C30-B30 -> 234.96 | D31: =D30-C30 -> 212.608 | E31: =E30-D30 -> 163.87272 | F31: =F30-E30 -> 144.47054 | G31: =G30-F30 -> 117.41776 | H31: =H30-G30 -> 103.99137 | I31: =I30-H30 -> 87.716149 | J31: =J30-I30 -> 68.911096 | K31: =K30-J30 -> 70.978429
A32: UNLEVERED FREE CASH FLOW | B32: =B27+B28-B29-B31 -> 183.8 | C32: =C27+C28-C29-C31 -> 905.268 | D32: =D27+D28-D29-D31 -> 1184.4872 | E32: =E27+E28-E29-E31 -> 1470.0861 | F32: =F27+F28-F29-F31 -> 1590.4338 | G32: =G27+G28-G29-G31 -> 1614.6938 | H32: =H27+H28-H29-H31 -> 1643.3802 | I32: =I27+I28-I29-I31 -> 1655.9434 | ... K32: =K27+K28-K29-K31 -> 1690.2545
A33: Economic EBIT margin | B33: =B25/B20 -> 0.305 | C33: =C25/C20 -> 0.295 | D33: =D25/D20 -> 0.285 | E33: =E25/E20 -> 0.275 | F33: =F25/F20 -> 0.265 | G33: =G25/G20 -> 0.245 | H33: =H25/H20 -> 0.23 | I33: =I25/I20 -> 0.215 | ... K33: =K25/K20 -> 0.205
A34: Economic EBITDA | B34: =B25+B28 -> 1932 | C34: =C25+C28 -> 2267.12 | D34: =D25+D28 -> 2557.524 | E34: =E25+E28 -> 2765.1611 | F34: =F25+F28 -> 2891.5073 | G34: =G25+G28 -> 2870.9032 | H34: =H25+H28 -> 2862.0741 | I34: =I25+I28 -> 2819.0903 | ... K34: =K25+K28 -> 2880.0035
A36: Remaining-year fraction | B36: =Summary!$B$25 -> 0.76986301 | C36: =1 -> 1 | D36: =1 -> 1 | E36: =1 -> 1 | F36: =1 -> 1 | G36: =1 -> 1 | H36: =1 -> 1 | I36: =1 -> 1 | J36: =1 -> 1 | K36: =1 -> 1
A37: Discount years | B37: =Summary!$B$25+0 -> 0.76986301 | C37: =Summary!$B$25+1 -> 1.769863 | D37: =Summary!$B$25+2 -> 2.769863 | E37: =Summary!$B$25+3 -> 3.769863 | F37: =Summary!$B$25+4 -> 4.769863 | G37: =Summary!$B$25+5 -> 5.769863 | H37: =Summary!$B$25+6 -> 6.769863 | I37: =Summary!$B$25+7 -> 7.769863 | J37: =Summary!$B$25+8 -> 8.769863 | K37: =Summary!$B$25+9 -> 9.769863
A38: Discount factor | B38: =1/(1+WACC!$B$26)^B37 -> 0.90420477 | C38: =1/(1+WACC!$B$26)^C37 -> 0.79334176 | D38: =1/(1+WACC!$B$26)^D37 -> 0.69607147 | E38: =1/(1+WACC!$B$26)^E37 -> 0.61072733 | F38: =1/(1+WACC!$B$26)^F37 -> 0.53584709 | G38: =1/(1+WACC!$B$26)^G37 -> 0.47014778 | H38: =1/(1+WACC!$B$26)^H37 -> 0.41250376 | I38: =1/(1+WACC!$B$26)^I37 -> 0.36192738 | ... K38: =1/(1+WACC!$B$26)^K37 -> 0.27861755
A39: PV of uFCF | B39: =B32*B36*B38 -> 127.94572 | C39: =C32*C36*C38 -> 718.1869 | D39: =D32*D36*D38 -> 824.48775 | E39: =E32*E36*E38 -> 897.82175 | F39: =F32*F36*F38 -> 852.22933 | G39: =G32*G36*G38 -> 759.14473 | H39: =H32*H36*H38 -> 677.90052 | I39: =I32*I36*I38 -> 599.33125 | ... K39: =K32*K36*K38 -> 470.93457
A41: TERMINAL VALUE: GORDON GROWTH AND MATURE EXIT EBITDA MULTIPLE
B42: Gordon | D42: Exit method
A43: Terminal revenue | B43: =K20*(1+WACC!B30) -> 11409.245
A44: Terminal NOPAT | B44: =B43*(K10-K11)*(1-K12) -> 1871.1161
A45: Terminal depreciation | B45: =B43*K13 -> 627.50846
A46: Terminal capex | B46: =B43*K14 -> 684.55469
A47: Terminal delta NWC | B47: =B43*K15-K30 -> 73.107782
A48: Normalized terminal uFCF | B48: =B44+B45-B46-B47 -> 1740.9621
...

Sheet WACC
A1: LITE | WACC
A3: USD millions / shares millions except prices. Blue = inputs; black = formulas. Thesis horizon: 3–6 months.
A5: NORMALIZED OPERATING RISK | NOT CALIBRATED TO A DESIRED SHARE PRICE
A7: Peer | B7: Beta | C7: Equity value | D7: Debt | E7: D/E | F7: Tax proxy | G7: Unlevered beta
A8: COHR | B8: 2.1 | C8: 57961.763 | D8: 3550 | E8: =D8/C8 -> 0.061247274 | F8: 0.25 | G8: =B8/(1+(1-F8)*E8) -> 2.0077721
A9: MRVL | B9: 2.25 | C9: 211129.67 | D9: 5290 | E9: =D9/C9 -> 0.025055692 | F9: 0.25 | G9: =B9/(1+(1-F9)*E9) -> 2.2084984
A10: FN | B10: 1.21 | C10: 13648.364 | D10: 4.01 | E10: =D10/C10 -> 0.00029380812 | F10: 0.25 | G10: =B10/(1+(1-F10)*E10) -> 1.2097334
A13: Risk-free rate [S6] | B13: 0.0494
A14: ERP observed [S7] | B14: 0.0414
A15: ERP selected | B15: 0.045
A16: Median peer unlevered beta | B16: =MEDIAN(G8:G10) -> 2.0077721
A17: Equity-equivalent market value | B17: =Capital!B31*Capital!B16 -> 92888.278
A18: Debt weight numerator | B18: =Capital!B9 -> 92.8
A19: Operating cash tax | B19: 0.2
A20: LITE relevered beta | B20: =B16*(1+(1-B19)*B18/B17) -> 2.0093768
A21: Cost of equity | B21: =B13+B20*B15 -> 0.13982195
A22: Debt credit spread assumption | B22: 0.025
A23: Pretax marginal cost of debt | B23: =B13+B22 -> 0.0744
A24: Debt weight | B24: =B18/(B17+B18) -> 0.00099805253
A25: Equity weight | B25: =1-B24 -> 0.99900195
A26: COMPONENT WACC | B26: =B21*B25+B23*(1-B19)*B24 -> 0.13974181
A28: Own observed LITE beta [S15] | B28: 1.54
A29: Own-beta WACC cross-check | B29: =(B13+B28*B15)*B25+B23*(1-B19)*B24 -> 0.11864094
A30: Terminal g | B30: 0.03
A31: Exit EBITDA multiple | B31: 16
A34: Beta source: public vendor 5-year betas, COHR / MRVL / FN [S8–S10]. Unlever with market D/E and a common 25% peer tax proxy; relever at LITE’s economic capital structure. All scenarios use the same WACC. No country premium or liquidity discount is added.
A36: In-money notes are equity equivalents in the primary valuation; therefore WACC financing debt is the $92.8m term debt. Their contractual cash-principal liquidity requirement remains explicit. Borrowing cost is Treasury + assumed 250bp credit spread, not the misleading 0.375–1.5% convertible coupons.
A38: Conservatism: selected ERP 4.50% exceeds the observed 4.14%; peer beta exceeds LITE’s own 1.54. A 3% terminal growth rate is below the roughly 4% long-run nominal benchmark (Fed June 2026: 2% real growth + 2% inflation). An independently sourced WACC is not proof the stock trades at fair value.

Sheet Capital
A1: LITE | CAPITAL
A3: USD millions / shares millions except prices. Blue = inputs; black = formulas. Thesis horizon: 3–6 months.
A5: REPORTED JUNE 27 CAPITAL | ONE CONSISTENT SNAPSHOT [S2]
A7: Cash | B7: 2043.5
A8: Short-term investments | B8: 694.9
A9: Nonconvertible term debt | B9: 92.8
A10: Common shares | B10: 88.6
A11: Preferred, one-for-one common equivalent | B11: 2.9
A12: RSUs outstanding | B12: 2
A13: PSUs outstanding, target payout | B13: 0.8
A14: Options outstanding | B14: 0.2
A15: Option exercise price | B15: 8.1
A16: Reference close: Sept 17 [S3] | B16: 893.61
A17: Option dilution: treasury method | B17: =B14*MAX(1-B15/B16,0) -> 0.19818713
A18: Core diluted shares before notes | B18: =SUM(B10:B13)+B17 -> 94.498187
A19: Minority interest claim | B19: 0
A20: Separate preferred senior claim | B20: 0
A21: Operating NWC, reported inputs | B21: 553.4
A23: CONVERTIBLES | CASH PRINCIPAL + PREMIUM SHARES AT FAIR VALUE
A24: Maturity | B24: Principal | C24: Conversion price | D24: Underlying shares
A25: 2026 | B25: 54.8 | C25: 99.29 | D25: =B25/C25 -> 0.55191862
A26: 2028 | B26: 179.6 | C26: 131.03 | D26: =B26/C26 -> 1.3706785
A27: 2029 | B27: 54.9 | C27: 69.54 | D27: =B27/C27 -> 0.78947368
A28: 2032 | B28: 1265 | C28: 187.77 | D28: =B28/C28 -> 6.7369654
B29: =SUM(B25:B28) -> 1554.3 | D29: =SUM(D25:D28) -> 9.4490362
A31: Full economic as-converted shares | B31: =B18+D29 -> 103.94722
A32: Cash less nonconvertible debt | B32: =B7+B8-B9 -> 2645.6
A33: Total debt principal | B33: =B9+B29 -> 1647.1
A35: Preferred has no senior liquidation/redemption claim; include its common-equivalent shares instead of deducting $2bn. Options use the treasury method at the dated reference price. RSUs/PSUs use full outstanding shares at target vesting; no unrecognized-compensation offset, a conservative simplification. Capped-call value excluded.
A37: Cash-settlement bridge subtracts all principal and divides by core shares plus only the conversion premium shares. Out-of-money notes remain debt. June cash/shares/debt are not mixed with August common shares. Post-June transactions and cash generation are not fully rolled forward.
A39: NWC = 520.3 AR + 691.6 inventory + 211.6 other current assets − 567.4 AP − 146.3 payroll − 64.9 accrued − 91.5 other current liabilities = 553.4. Leases remain operating costs; no second lease-debt deduction.

Sheet Sensitivity
A1: LITE | SENSITIVITY
A3: USD millions / shares millions except prices. Blue = inputs; black = formulas. Thesis horizon: 3–6 months.
A5: BULL | WACC × TERMINAL GROWTH | $/SHARE
B7: 0.02 | C7: 0.025 | D7: 0.03 | E7: 0.035 | F7: 0.04
